{
    "parts": [
        {
            "x": 4,
            "y": 2,
            "z": -3,
            "elements": [
                "immersiveengineering:metal_multiblock@2"
            ]
        },
        {
            "x": -1,
            "y": 0,
            "z": 0,
            "elements": [
                "immersiveengineering:treated_wood_stairs0@0"
            ]
        },
        {
            "x": 2,
            "y": 4,
            "z": 2,
            "elements": [
                "immersiveengineering:metal_multiblock@2"
            ]
        },
        {
            "x": 1,
            "y": 2,
            "z": 1,
            "elements": [
                "immersiveengineering:metal_multiblock@2"
            ]
        },
        {
            "x": 4,
            "y": 4,
            "z": -2,
            "elements": [
                "immersiveengineering:metal_multiblock@2"
            ]
        },
        {
            "x": 2,
            "y": 0,
            "z": -4,
            "elements": [
                "immersiveengineering:metal_multiblock@2"
            ]
        },
        {
            "x": 3,
            "y": 4,
            "z": 2,
            "elements": [
                "immersiveengineering:metal_multiblock@2"
            ]
        },
        {
            "x": 2,
            "y": 2,
            "z": 1,
            "elements": [
                "immersiveengineering:metal_multiblock@2"
            ]
        },
        {
            "x": 1,
            "y": 0,
            "z": 0,
            "elements": [
                "immersiveengineering:treated_wood_stairs0@1"
            ]
        },
        {
            "x": 4,
            "y": 4,
            "z": 2,
            "elements": [
                "immersiveengineering:metal_multiblock@2"
            ]
        },
        {
            "x": 2,
            "y": 0,
            "z": 0,
            "elements": [
                "adchimneys:blastbrick@1"
            ]
        },
        {
            "x": 3,
            "y": 4,
            "z": -2,
            "elements": [
                "immersiveengineering:metal_multiblock@2"
            ]
        },
        {
            "x": 2,
            "y": 2,
            "z": -3,
            "elements": [
                "immersiveengineering:metal_multiblock@2"
            ]
        },
        {
            "x": 2,
            "y": 4,
            "z": -2,
            "elements": [
                "immersiveengineering:metal_multiblock@2"
            ]
        },
        {
            "x": 4,
            "y": 2,
            "z": 1,
            "elements": [
                "immersiveengineering:metal_multiblock@2"
            ]
        },
        {
            "x": 3,
            "y": 0,
            "z": 0,
            "elements": [
                "adchimneys:blastbrick@1"
            ]
        },
        {
            "x": 4,
            "y": 0,
            "z": 0,
            "elements": [
                "adchimneys:blastbrick@1"
            ]
        },
        {
            "x": 4,
            "y": -1,
            "z": 0,
            "elements": [
                "immersiveengineering:treated_wood@0"
            ]
        },
        {
            "x": 3,
            "y": -1,
            "z": 0,
            "elements": [
                "immersiveengineering:treated_wood@0"
            ]
        },
        {
            "x": 2,
            "y": -1,
            "z": 0,
            "elements": [
                "immersiveengineering:treated_wood@0"
            ]
        },
        {
            "x": -1,
            "y": 3,
            "z": 1,
            "elements": [
                "immersiveengineering:metal_multiblock@2"
            ]
        },
        {
            "x": 0,
            "y": 5,
            "z": 2,
            "elements": [
                "immersiveengineering:metal_device1@6"
            ]
        },
        {
            "x": 1,
            "y": -1,
            "z": 0,
            "elements": [
                "immersiveengineering:treated_wood@0"
            ]
        },
        {
            "x": 0,
            "y": -1,
            "z": 0,
            "elements": [
                "immersiveengineering:treated_wood@0"
            ]
        },
        {
            "x": 0,
            "y": 3,
            "z": 1,
            "elements": [
                "immersiveengineering:metal_multiblock@2"
            ]
        },
        {
            "x": 4,
            "y": -1,
            "z": -4,
            "elements": [
                "immersiveengineering:treated_wood@0"
            ]
        },
        {
            "x": 2,
            "y": 5,
            "z": 2,
            "elements": [
                "immersiveengineering:metal_multiblock@2"
            ]
        },
        {
            "x": 1,
            "y": 3,
            "z": 1,
            "elements": [
                "immersiveengineering:metal_multiblock@2"
            ]
        },
        {
            "x": 4,
            "y": 1,
            "z": -3,
            "elements": [
                "immersiveengineering:metal_multiblock@2"
            ]
        },
        {
            "x": 3,
            "y": -1,
            "z": -4,
            "elements": [
                "modularmachinery:blockcasing@0"
            ]
        },
        {
            "x": -1,
            "y": -1,
            "z": 0,
            "elements": [
                "immersiveengineering:treated_wood@0"
            ]
        },
        {
            "x": 4,
            "y": 3,
            "z": -2,
            "elements": [
                "immersiveengineering:metal_multiblock@2"
            ]
        },
        {
            "x": 2,
            "y": -1,
            "z": -4,
            "elements": [
                "immersiveengineering:metal_decoration0@4"
            ]
        },
        {
            "x": 3,
            "y": 5,
            "z": 2,
            "elements": [
                "immersiveengineering:metal_multiblock@2"
            ]
        },
        {
            "x": 4,
            "y": 5,
            "z": 2,
            "elements": [
                "immersiveengineering:metal_multiblock@2"
            ]
        },
        {
            "x": 2,
            "y": 1,
            "z": 0,
            "elements": [
                "immersiveengineering:metal_multiblock@2"
            ]
        },
        {
            "x": 3,
            "y": 3,
            "z": -2,
            "elements": [
                "immersiveengineering:metal_multiblock@2"
            ]
        },
        {
            "x": 2,
            "y": 1,
            "z": -3,
            "elements": [
                "immersiveengineering:metal_multiblock@2"
            ]
        },
        {
            "x": 1,
            "y": -1,
            "z": -4,
            "elements": [
                "immersiveengineering:treated_wood_slab@0"
            ]
        },
        {
            "x": 0,
            "y": -1,
            "z": -4,
            "elements": [
                "immersiveengineering:treated_wood_slab@0"
            ]
        },
        {
            "x": 3,
            "y": 1,
            "z": 0,
            "elements": [
                "immersiveengineering:metal_device1@6"
            ]
        },
        {
            "x": 2,
            "y": 3,
            "z": -2,
            "elements": [
                "immersiveengineering:metal_multiblock@2"
            ]
        },
        {
            "x": 4,
            "y": 1,
            "z": 0,
            "elements": [
                "immersiveengineering:metal_multiblock@2"
            ]
        },
        {
            "x": -1,
            "y": -1,
            "z": -4,
            "elements": [
                "immersiveengineering:treated_wood_slab@0"
            ]
        },
        {
            "x": -1,
            "y": -1,
            "z": 3,
            "elements": [
                "immersiveengineering:treated_wood@0"
            ]
        },
        {
            "x": 0,
            "y": -1,
            "z": 3,
            "elements": [
                "modularmachinery:blockcasing@0"
            ]
        },
        {
            "x": 1,
            "y": -1,
            "z": 3,
            "elements": [
                "immersiveengineering:treated_wood@0"
            ]
        },
        {
            "x": 2,
            "y": -1,
            "z": 3,
            "elements": [
                "immersiveengineering:treated_wood@0"
            ]
        },
        {
            "x": 3,
            "y": -1,
            "z": 3,
            "elements": [
                "immersiveengineering:treated_wood@0"
            ]
        },
        {
            "x": 4,
            "y": -1,
            "z": 3,
            "elements": [
                "immersiveengineering:treated_wood@0"
            ]
        },
        {
            "x": -1,
            "y": 4,
            "z": 1,
            "elements": [
                "immersiveengineering:metal_multiblock@2"
            ]
        },
        {
            "x": 0,
            "y": 6,
            "z": 2,
            "elements": [
                "immersiveengineering:metal_device1@6"
            ]
        },
        {
            "x": 1,
            "y": 6,
            "z": 2,
            "elements": [
                "immersiveengineering:metal_device1@6"
            ]
        },
        {
            "x": 0,
            "y": 4,
            "z": 1,
            "elements": [
                "immersiveengineering:metal_multiblock@2"
            ]
        },
        {
            "x": 2,
            "y": 6,
            "z": 2,
            "elements": [
                "immersiveengineering:metal_device1@6"
            ]
        },
        {
            "x": 1,
            "y": 4,
            "z": 1,
            "elements": [
                "immersiveengineering:metal_multiblock@2"
            ]
        },
        {
            "x": 4,
            "y": 2,
            "z": -2,
            "elements": [
                "immersiveengineering:metal_multiblock@2"
            ]
        },
        {
            "x": 3,
            "y": 0,
            "z": -3,
            "elements": [
                "immersiveengineering:metal_multiblock@2"
            ]
        },
        {
            "x": 3,
            "y": 6,
            "z": 2,
            "elements": [
                "immersiveengineering:metal_device1@6"
            ]
        },
        {
            "x": 3,
            "y": 2,
            "z": -2,
            "elements": [
                "immersiveengineering:metal_multiblock@2"
            ]
        },
        {
            "x": 2,
            "y": 2,
            "z": 0,
            "elements": [
                "immersiveengineering:metal_multiblock@2"
            ]
        },
        {
            "x": 3,
            "y": 2,
            "z": 0,
            "elements": [
                "immersiveengineering:metal_multiblock@2"
            ]
        },
        {
            "x": 2,
            "y": 2,
            "z": -2,
            "elements": [
                "immersiveengineering:metal_multiblock@2"
            ]
        },
        {
            "x": 4,
            "y": 2,
            "z": 0,
            "elements": [
                "immersiveengineering:metal_multiblock@2"
            ]
        },
        {
            "x": -1,
            "y": 0,
            "z": 3,
            "elements": [
                "immersiveengineering:metal_multiblock@2"
            ]
        },
        {
            "x": 1,
            "y": 0,
            "z": 3,
            "elements": [
                "immersiveengineering:metal_multiblock@2"
            ]
        },
        {
            "x": 4,
            "y": -1,
            "z": -3,
             "elements": [
                "modularmachinery:blockcasing@0"
            ]
        },
        {
            "x": 2,
            "y": 5,
            "z": 1,
            "elements": [
                "immersiveengineering:metal_multiblock@2"
            ]
        },
        {
            "x": 4,
            "y": 1,
            "z": -2,
            "elements": [
                "immersiveengineering:metal_multiblock@2"
            ]
        },
        {
            "x": 3,
            "y": -1,
            "z": -3,
            "elements": [
                "immersiveengineering:treated_wood@0"
            ]
        },
        {
            "x": 2,
            "y": -1,
            "z": -3,
            "elements": [
                "modularmachinery:blockcasing@0"
            ]
        },
        {
            "x": 2,
            "y": 3,
            "z": 0,
            "elements": [
                "immersiveengineering:metal_multiblock@2"
            ]
        },
        {
            "x": 4,
            "y": 5,
            "z": 1,
            "elements": [
                "immersiveengineering:metal_multiblock@2"
            ]
        },
        {
            "x": 3,
            "y": 3,
            "z": 0,
            "elements": [
                "immersiveengineering:metal_multiblock@2"
            ]
        },
        {
            "x": 2,
            "y": 1,
            "z": -2,
            "elements": [
                "immersiveengineering:metal_multiblock@2"
            ]
        },
        {
            "x": 1,
            "y": -1,
            "z": -3,
            "elements": [
                "immersiveengineering:treated_wood_slab@0"
            ]
        },
        {
            "x": 0,
            "y": -1,
            "z": -3,
            "elements": [
                "immersiveengineering:treated_wood_slab@0"
            ]
        },
        {
            "x": 4,
            "y": 3,
            "z": 0,
            "elements": [
                "immersiveengineering:metal_multiblock@2"
            ]
        },
        {
            "x": -1,
            "y": 1,
            "z": 3,
            "elements": [
                "immersiveengineering:metal_multiblock@2"
            ]
        },
        {
            "x": 0,
            "y": 1,
            "z": 3,
            "elements": [
                "immersiveengineering:metal_multiblock@2"
            ]
        },
        {
            "x": -1,
            "y": -1,
            "z": -3,
            "elements": [
                "immersiveengineering:treated_wood_slab@0"
            ]
        },
        {
            "x": -1,
            "y": -1,
            "z": 2,
            "elements": [
                "modularmachinery:blockcasing@0"
            ]
        },
        {
            "x": 0,
            "y": -1,
            "z": 2,
            "elements": [
                "immersiveengineering:treated_wood@0"
            ]
        },
        {
            "x": 1,
            "y": 1,
            "z": 3,
            "elements": [
                "immersiveengineering:metal_multiblock@2"
            ]
        },
        {
            "x": 1,
            "y": -1,
            "z": 2,
            "elements": [
                "immersiveengineering:treated_wood@0"
            ]
        },
        {
            "x": 2,
            "y": -1,
            "z": 2,
            "elements": [
                "immersiveengineering:treated_wood@0"
            ]
        },
        {
            "x": 3,
            "y": -1,
            "z": 2,
            "elements": [
                "immersiveengineering:treated_wood@0"
            ]
        },
        {
            "x": 4,
            "y": -1,
            "z": 2,
            "elements": [
                "immersiveengineering:treated_wood@0"
            ]
        },
        {
            "x": 4,
            "y": 0,
            "z": -2,
            "elements": [
                "immersiveengineering:metal_multiblock@2"
            ]
        },
        {
            "x": 3,
            "y": 0,
            "z": -2,
            "elements": [
                "immersiveengineering:metal_device1@6"
            ]
        },
        {
            "x": 3,
            "y": 6,
            "z": 1,
            "elements": [
                "immersiveengineering:metal_device1@6"
            ]
        },
        {
            "x": 2,
            "y": 4,
            "z": 0,
            "elements": [
                "immersiveengineering:metal_multiblock@2"
            ]
        },
        {
            "x": 2,
            "y": 0,
            "z": -2,
            "elements": [
                "immersiveengineering:metal_multiblock@2"
            ]
        },
        {
            "x": 3,
            "y": 4,
            "z": 0,
            "elements": [
                "immersiveengineering:metal_multiblock@2"
            ]
        },
        {
            "x": 4,
            "y": 4,
            "z": 0,
            "elements": [
                "immersiveengineering:metal_multiblock@2"
            ]
        },
        {
            "x": -1,
            "y": 2,
            "z": 3,
            "elements": [
                "immersiveengineering:metal_multiblock@2"
            ]
        },
        {
            "x": 0,
            "y": 2,
            "z": 3,
            "elements": [
                "immersiveengineering:metal_multiblock@2"
            ]
        },
        {
            "x": 0,
            "y": 0,
            "z": 2,
            "elements": [
                "immersiveengineering:metal_multiblock@2"
            ]
        },
        {
            "x": 1,
            "y": 2,
            "z": 3,
            "elements": [
                "immersiveengineering:metal_multiblock@2"
            ]
        },
        {
            "x": 4,
            "y": 4,
            "z": -4,
            "elements": [
                "immersiveengineering:metal_multiblock@2"
            ]
        },
        {
            "x": 2,
            "y": 0,
            "z": 2,
            "elements": [
                "adchimneys:blastbrick@1"
            ]
        },
        {
            "x": 3,
            "y": 4,
            "z": -4,
            "elements": [
                "immersiveengineering:metal_multiblock@2"
            ]
        },
        {
            "x": 2,
            "y": 4,
            "z": -4,
            "elements": [
                "immersiveengineering:metal_multiblock@2"
            ]
        },
        {
            "x": 3,
            "y": 0,
            "z": 2,
            "elements": [
                "adchimneys:blastbrick@1"
            ]
        },
        {
            "x": 4,
            "y": 0,
            "z": 2,
            "elements": [
                "adchimneys:blastbrick@1"
            ]
        },
        {
            "x": 4,
            "y": -1,
            "z": -2,
            "elements": [
                "immersiveengineering:treated_wood@0"
            ]
        },
        {
            "x": 2,
            "y": 5,
            "z": 0,
            "elements": [
                "immersiveengineering:metal_multiblock@2"
            ]
        },
        {
            "x": 3,
            "y": -1,
            "z": -2,
            "elements": [
                "immersiveengineering:treated_wood@0"
            ]
        },
        {
            "x": 3,
            "y": 1,
            "z": -1,
            "elements": [
                "immersiveengineering:metal_device1@6"
            ]
        },
        {
            "x": 2,
            "y": -1,
            "z": -2,
            "elements": [
                "immersiveengineering:metal_decoration0@4"
            ]
        },
        {
            "x": 3,
            "y": 5,
            "z": 0,
            "elements": [
                "immersiveengineering:metal_multiblock@2"
            ]
        },
        {
            "x": -1,
            "y": 3,
            "z": 3,
            "elements": [
                "immersiveengineering:metal_multiblock@2"
            ]
        },
        {
            "x": 4,
            "y": 5,
            "z": 0,
            "elements": [
                "immersiveengineering:metal_multiblock@2"
            ]
        },
        {
            "x": 1,
            "y": -1,
            "z": -2,
            "elements": [
                "immersiveengineering:treated_wood_slab@0"
            ]
        },
        {
            "x": 0,
            "y": -1,
            "z": -2,
            "elements": [
                "immersiveengineering:treated_wood_slab@0"
            ]
        },
        {
            "x": 0,
            "y": 3,
            "z": 3,
            "elements": [
                "immersiveengineering:metal_multiblock@2"
            ]
        },
        {
            "x": 1,
            "y": 3,
            "z": 3,
            "elements": [
                "immersiveengineering:metal_multiblock@2"
            ]
        },
        {
            "x": -1,
            "y": -1,
            "z": -2,
            "elements": [
                "immersiveengineering:treated_wood_slab@0"
            ]
        },
        {
            "x": -1,
            "y": -1,
            "z": 1,
            "elements": [
                "immersiveengineering:treated_wood@0"
            ]
        },
        {
            "x": 0,
            "y": -1,
            "z": 1,
            "elements": [
                "immersiveengineering:treated_wood@0"
            ]
        },
        {
            "x": 4,
            "y": 3,
            "z": -4,
            "elements": [
                "immersiveengineering:metal_multiblock@2"
            ]
        },
        {
            "x": 1,
            "y": 1,
            "z": 2,
            "elements": [
                "immersiveengineering:metal_multiblock@2"
            ]
        },
        {
            "x": 2,
            "y": 1,
            "z": 2,
            "elements": [
                "immersiveengineering:metal_multiblock@2"
            ]
        },
        {
            "x": 1,
            "y": -1,
            "z": 1,
            "elements": [
                "immersiveengineering:treated_wood@0"
            ]
        },
        {
            "x": 3,
            "y": 3,
            "z": -4,
            "elements": [
                "immersiveengineering:metal_multiblock@2"
            ]
        },
        {
            "x": 2,
            "y": -1,
            "z": 1,
            "elements": [
                "immersiveengineering:treated_wood@0"
            ]
        },
        {
            "x": 2,
            "y": 3,
            "z": -4,
             "elements": [
                "immersiveengineering:metal_multiblock@2"
            ]
        },
        {
            "x": 4,
            "y": 1,
            "z": 2,
            "elements": [
                "immersiveengineering:metal_multiblock@2"
            ]
        },
        {
            "x": 3,
            "y": -1,
            "z": 1,
            "elements": [
                "immersiveengineering:treated_wood@0"
            ]
        },
        {
            "x": 4,
            "y": -1,
            "z": 1,
            "elements": [
                "immersiveengineering:treated_wood@0"
            ]
        },
        {
            "x": 3,
            "y": 0,
            "z": -1,
            "elements": [
                "immersiveengineering:metal_device1@6"
            ]
        },
        {
            "x": -1,
            "y": 4,
            "z": 3,
            "elements": [
                "immersiveengineering:metal_multiblock@2"
            ]
        },
        {
            "x": 0,
            "y": 4,
            "z": 3,
            "elements": [
                "immersiveengineering:metal_multiblock@2"
            ]
        },
        {
            "x": -1,
            "y": 2,
            "z": 2,
            "elements": [
                "immersiveengineering:metal_multiblock@2"
            ]
        },
        {
            "x": 1,
            "y": 4,
            "z": 3,
            "elements": [
                "immersiveengineering:metal_multiblock@2"
            ]
        },
        {
            "x": -1,
            "y": 0,
            "z": 1,
            "elements": [
                "immersiveengineering:metal_multiblock@2"
            ]
        },
        {
            "x": 4,
            "y": 2,
            "z": -4,
            "elements": [
                "immersiveengineering:metal_multiblock@2"
            ]
        },
        {
            "x": 4,
            "y": 4,
            "z": -3,
            "elements": [
                "immersiveengineering:metal_multiblock@2"
            ]
        },
        {
            "x": 3,
            "y": 2,
            "z": -4,
            "elements": [
                "immersiveengineering:metal_multiblock@2"
            ]
        },
        {
            "x": 2,
            "y": 2,
            "z": 2,
            "nbt": {"offset":,"pos":"11","ForgeCaps":{"nuclearcraft:capability_default_radiation_resistance":{"radiationResistance":"0.0d"}},"facing":"5","id":"immersiveengineering:sheetmetaltank","formed":"1b","tank":{"Empty":""},"mirrored":"0b"},
            "elements": [
                "immersiveengineering:metal_multiblock@2"
            ]
        },
        {
            "x": 3,
            "y": 2,
            "z": 2,
            "nbt": {"offset":,"pos":"14","ForgeCaps":{"nuclearcraft:capability_default_radiation_resistance":{"radiationResistance":"0.0d"}},"facing":"5","id":"immersiveengineering:sheetmetaltank","formed":"1b","tank":{"Empty":""},"mirrored":"0b"},
            "elements": [
                "immersiveengineering:metal_multiblock@2"
            ]
        },
        {
            "x": 2,
            "y": 0,
            "z": 1,
            "elements": [
                "adchimneys:blastbrick@1"
            ]
        },
        {
            "x": 3,
            "y": 4,
            "z": -3,
            "nbt": {"offset":,"pos":"40","ForgeCaps":{"nuclearcraft:capability_default_radiation_resistance":{"radiationResistance":"0.0d"}},"facing":"3","id":"immersiveengineering:sheetmetaltank","formed":"1b","tank":{"Empty":""},"mirrored":"0b"},
            "elements": [
                "immersiveengineering:metal_multiblock@2"
            ]
        },
        {
            "x": 2,
            "y": 2,
            "z": -4,
            "nbt": {"offset":,"pos":"24","ForgeCaps":{"nuclearcraft:capability_default_radiation_resistance":{"radiationResistance":"0.0d"}},"facing":"3","id":"immersiveengineering:sheetmetaltank","formed":"1b","tank":{"Empty":""},"mirrored":"0b"},
            "elements": [
                "immersiveengineering:metal_multiblock@2"
            ]
        },
        {
            "x": 2,
            "y": 4,
            "z": -3,
            "nbt": {"offset":,"pos":"39","ForgeCaps":{"nuclearcraft:capability_default_radiation_resistance":{"radiationResistance":"0.0d"}},"facing":"3","id":"immersiveengineering:sheetmetaltank","formed":"1b","tank":{"Empty":""},"mirrored":"0b"},
            "elements": [
                "immersiveengineering:metal_multiblock@2"
            ]
        },
        {
            "x": 4,
            "y": 2,
            "z": 2,
            "nbt": {"offset":,"pos":"17","ForgeCaps":{"nuclearcraft:capability_default_radiation_resistance":{"radiationResistance":"0.0d"}},"facing":"5","id":"immersiveengineering:sheetmetaltank","formed":"1b","tank":{"Empty":""},"mirrored":"0b"},
            "elements": [
                "immersiveengineering:metal_multiblock@2"
            ]
        },
        {
            "x": 3,
            "y": 0,
            "z": 1,
            "nbt": {"ForgeCaps":{"nuclearcraft:capability_default_radiation_resistance":{"radiationResistance":"0.0d"}},"facing":"1","active":"0b","ifluxEnergy":"0","id":"immersiveengineering:furnaceheater"},
            "elements": [
                "immersiveengineering:metal_device1@1"
            ]
        },
        {
            "x": 4,
            "y": 0,
            "z": 1,
            "elements": [
                "adchimneys:blastbrick@1"
            ]
        },
        {
            "x": 4,
            "y": -1,
            "z": -1,
            "elements": [
                "immersiveengineering:treated_wood@0"
            ]
        },
        {
            "x": 3,
            "y": -1,
            "z": -1,
            "elements": [
                "immersiveengineering:treated_wood@0"
            ]
        },
        {
            "x": 2,
            "y": -1,
            "z": -1,
            "elements": [
                "immersiveengineering:treated_wood@0"
            ]
        },
        {
            "x": -1,
            "y": 3,
            "z": 2,
            "nbt": {"offset":,"pos":"30","ForgeCaps":{"nuclearcraft:capability_default_radiation_resistance":{"radiationResistance":"0.0d"}},"facing":"3","id":"immersiveengineering:sheetmetaltank","formed":"1b","tank":{"Empty":""},"mirrored":"0b"},
            "elements": [
                "immersiveengineering:metal_multiblock@2"
            ]
        },
        {
            "x": 1,
            "y": -1,
            "z": -1,
            "nbt": {"ForgeCaps":{"nuclearcraft:capability_default_radiation_resistance":{"radiationResistance":"0.0d"}},"id":"immersiveengineering:ieslab","slabType":"0"},
            "elements": [
                "immersiveengineering:treated_wood_slab@0"
            ]
        },
        {
            "x": 0,
            "y": -1,
            "z": -1,
            "nbt": {"ForgeCaps":{"nuclearcraft:capability_default_radiation_resistance":{"radiationResistance":"0.0d"}},"id":"immersiveengineering:ieslab","slabType":"0"},
            "elements": [
                "immersiveengineering:treated_wood_slab@0"
            ]
        },
        {
            "x": -1,
            "y": 1,
            "z": 1,
            "nbt": {"offset":,"pos":"15","ForgeCaps":{"nuclearcraft:capability_default_radiation_resistance":{"radiationResistance":"0.0d"}},"facing":"3","id":"immersiveengineering:sheetmetaltank","formed":"1b","tank":{"Empty":""},"mirrored":"0b"},
            "elements": [
                "immersiveengineering:metal_multiblock@2"
            ]
        },
        {
            "x": 0,
            "y": 1,
            "z": 1,
            "nbt": {"offset":,"pos":"16","ForgeCaps":{"nuclearcraft:capability_default_radiation_resistance":{"radiationResistance":"0.0d"}},"facing":"3","id":"immersiveengineering:sheetmetaltank","formed":"1b","tank":{"Empty":""},"mirrored":"0b"},
            "elements": [
                "immersiveengineering:metal_multiblock@2"
            ]
        },
        {
            "x": 4,
            "y": 1,
            "z": -4,
            "nbt": {"offset":,"pos":"17","ForgeCaps":{"nuclearcraft:capability_default_radiation_resistance":{"radiationResistance":"0.0d"}},"facing":"3","id":"immersiveengineering:sheetmetaltank","formed":"1b","tank":{"Empty":""},"mirrored":"0b"},
            "elements": [
                "immersiveengineering:metal_multiblock@2"
            ]
        },
        {
            "x": -1,
            "y": -1,
            "z": -1,
            "nbt": {"ForgeCaps":{"nuclearcraft:capability_default_radiation_resistance":{"radiationResistance":"0.0d"}},"id":"immersiveengineering:ieslab","slabType":"0"},
            "elements": [
                "immersiveengineering:treated_wood_slab@0"
            ]
        },
        {
            "x": 4,
            "y": 3,
            "z": -3,
            "nbt": {"offset":,"pos":"32","ForgeCaps":{"nuclearcraft:capability_default_radiation_resistance":{"radiationResistance":"0.0d"}},"facing":"3","id":"immersiveengineering:sheetmetaltank","formed":"1b","tank":{"Empty":""},"mirrored":"0b"},
            "elements": [
                "immersiveengineering:metal_multiblock@2"
            ]
        },
        {
            "x": 3,
            "y": 1,
            "z": -4,
            "nbt": {"offset":,"pos":"16","ForgeCaps":{"nuclearcraft:capability_default_radiation_resistance":{"radiationResistance":"0.0d"}},"facing":"3","id":"immersiveengineering:sheetmetaltank","formed":"1b","tank":{"Empty":""},"mirrored":"0b"},
            "elements": [
                "immersiveengineering:metal_multiblock@2"
            ]
        },
        {
            "x": 2,
            "y": 3,
            "z": 2,
            "nbt": {"offset":,"pos":"20","ForgeCaps":{"nuclearcraft:capability_default_radiation_resistance":{"radiationResistance":"0.0d"}},"facing":"5","id":"immersiveengineering:sheetmetaltank","formed":"1b","tank":{"Empty":""},"mirrored":"0b"},
            "elements": [
                "immersiveengineering:metal_multiblock@2"
            ]
        },
        {
            "x": 1,
            "y": 1,
            "z": 1,
            "nbt": {"offset":,"pos":"17","ForgeCaps":{"nuclearcraft:capability_default_radiation_resistance":{"radiationResistance":"0.0d"}},"facing":"3","id":"immersiveengineering:sheetmetaltank","formed":"1b","tank":{"Empty":""},"mirrored":"0b"},
            "elements": [
                "immersiveengineering:metal_multiblock@2"
            ]
        },
        {
            "x": 3,
            "y": 3,
            "z": 2,
            "nbt": {"offset":,"pos":"23","ForgeCaps":{"nuclearcraft:capability_default_radiation_resistance":{"radiationResistance":"0.0d"}},"facing":"5","id":"immersiveengineering:sheetmetaltank","formed":"1b","tank":{"Empty":""},"mirrored":"0b"},
            "elements": [
                "immersiveengineering:metal_multiblock@2"
            ]
        },
        {
            "x": 2,
            "y": 1,
            "z": -4,
            "nbt": {"offset":,"pos":"15","ForgeCaps":{"nuclearcraft:capability_default_radiation_resistance":{"radiationResistance":"0.0d"}},"facing":"3","id":"immersiveengineering:sheetmetaltank","formed":"1b","tank":{"Empty":""},"mirrored":"0b"},
            "elements": [
                "immersiveengineering:metal_multiblock@2"
            ]
        },
        {
            "x": 4,
            "y": 3,
            "z": 2,
            "nbt": {"offset":,"pos":"26","ForgeCaps":{"nuclearcraft:capability_default_radiation_resistance":{"radiationResistance":"0.0d"}},"facing":"5","id":"immersiveengineering:sheetmetaltank","formed":"1b","tank":{"Empty":""},"mirrored":"0b"},
            "elements": [
                "immersiveengineering:metal_multiblock@2"
            ]
        },
        {
            "x": 3,
            "y": 1,
            "z": 1,
            "nbt": {"offset":,"pos":"4","ForgeCaps":{"nuclearcraft:capability_default_radiation_resistance":{"radiationResistance":"0.0d"}},"facing":"5","id":"immersiveengineering:sheetmetaltank","formed":"1b","tank":{"Empty":""},"mirrored":"0b"},
            "elements": [
                "immersiveengineering:metal_multiblock@2"
            ]
        },
        {
            "x": 2,
            "y": 3,
            "z": -3,
            "nbt": {"offset":,"pos":"30","ForgeCaps":{"nuclearcraft:capability_default_radiation_resistance":{"radiationResistance":"0.0d"}},"facing":"3","id":"immersiveengineering:sheetmetaltank","formed":"1b","tank":{"Empty":""},"mirrored":"0b"},
            "elements": [
                "immersiveengineering:metal_multiblock@2"
            ]
        },
        {
            "x": -1,
            "y": 4,
            "z": 2,
            "nbt": {"offset":,"pos":"39","ForgeCaps":{"nuclearcraft:capability_default_radiation_resistance":{"radiationResistance":"0.0d"}},"facing":"3","id":"immersiveengineering:sheetmetaltank","formed":"1b","tank":{"Empty":""},"mirrored":"0b"},
            "elements": [
                "immersiveengineering:metal_multiblock@2"
            ]
        },
        {
            "x": -1,
            "y": 2,
            "z": 1,
            "nbt": {"offset":,"pos":"24","ForgeCaps":{"nuclearcraft:capability_default_radiation_resistance":{"radiationResistance":"0.0d"}},"facing":"3","id":"immersiveengineering:sheetmetaltank","formed":"1b","tank":{"Empty":""},"mirrored":"0b"},
            "elements": [
                "immersiveengineering:metal_multiblock@2"
            ]
        },
        {
            "x": 4,
            "y": 0,
            "z": -4,
            "nbt": {"offset":,"pos":"8","ForgeCaps":{"nuclearcraft:capability_default_radiation_resistance":{"radiationResistance":"0.0d"}},"facing":"3","id":"immersiveengineering:sheetmetaltank","formed":"1b","tank":{"Empty":""},"mirrored":"0b"},
            "elements": [
                "immersiveengineering:metal_multiblock@2"
            ]
        },
        {
            "x": 1,
            "y": 4,
            "z": 2,
            "nbt": {"offset":,"pos":"41","ForgeCaps":{"nuclearcraft:capability_default_radiation_resistance":{"radiationResistance":"0.0d"}},"facing":"3","id":"immersiveengineering:sheetmetaltank","formed":"1b","tank":{"Empty":""},"mirrored":"0b"},
            "elements": [
                "immersiveengineering:metal_multiblock@2"
            ]
        },
        {
            "x": 0,
            "y": 2,
            "z": 1,
            "nbt": {"offset":,"pos":"25","ForgeCaps":{"nuclearcraft:capability_default_radiation_resistance":{"radiationResistance":"0.0d"}},"facing":"3","id":"immersiveengineering:sheetmetaltank","formed":"1b","tank":{"Empty":""},"mirrored":"0b"},
            "elements": [
                "immersiveengineering:metal_multiblock@2"
            ]
        }
    ]}