{
    "parts": [
        {
            "x": -2,
            "y": 0,
            "z": 2,
            "elements": [
                "astralsorcery:blockmarble@2"
            ]
        },
        {
            "x": -1,
            "y": 0,
            "z": 0,
            "nbt": {"casingColor":"16777215","ForgeCaps":{"nuclearcraft:capability_default_radiation_resistance":{"radiationResistance":"0.0d"}},"id":"minecraft:tilecolorablemachinecomponent"},
            "elements": [
                "modularmachinery:blockcasing@0"
            ]
        },
        {
            "x": -2,
            "y": 0,
            "z": 0,
            "elements": [
                "astralsorcery:blockmarble@2"
            ]
        },
        {
            "x": 2,
            "y": 2,
            "z": 1,
            "elements": [
                "astralsorcery:blockmarbleslab@0"
            ]
        },
        {
            "x": 1,
            "y": 0,
            "z": 0,
            "nbt": {"casingColor":"16777215","ForgeCaps":{"nuclearcraft:capability_default_radiation_resistance":{"radiationResistance":"0.0d"}},"id":"minecraft:tilecolorablemachinecomponent"},
            "elements": [
                "modularmachinery:blockcasing@0"
            ]
        },
        {
            "x": -1,
            "y": 0,
            "z": 2,
            "nbt": {"casingColor":"16777215","ForgeCaps":{"nuclearcraft:capability_default_radiation_resistance":{"radiationResistance":"0.0d"}},"id":"minecraft:tilecolorablemachinecomponent"},
            "elements": [
                "modularmachinery:blockcasing@0"
            ]
        },
        {
            "x": 0,
            "y": 0,
            "z": 2,
            "nbt": {"casingColor":"16777215","ForgeCaps":{"nuclearcraft:capability_default_radiation_resistance":{"radiationResistance":"0.0d"}},"id":"minecraft:tilecolorablemachinecomponent"},
            "elements": [
                "modularmachinery:blockcasing@0"
            ]
        },
        {
            "x": 2,
            "y": 0,
            "z": 0,
            "elements": [
                "astralsorcery:blockmarble@2"
            ]
        },
        {
            "x": 1,
            "y": 0,
            "z": 2,
            "nbt": {"casingColor":"16777215","ForgeCaps":{"nuclearcraft:capability_default_radiation_resistance":{"radiationResistance":"0.0d"}},"id":"minecraft:tilecolorablemachinecomponent"},
            "elements": [
                "modularmachinery:blockcasing@0"
            ]
        },
        {
            "x": 2,
            "y": 0,
            "z": 2,
            "elements": [
                "astralsorcery:blockmarble@2"
            ]
        },
        {
            "x": 2,
            "y": -1,
            "z": 0,
            "elements": [
                "astralsorcery:blockmarble@6"
            ]
        },
        {
            "x": 1,
            "y": -1,
            "z": 0,
            "elements": [
                "astralsorcery:blockmarble@6"
            ]
        },
        {
            "x": -2,
            "y": 1,
            "z": 0,
            "elements": [
                "astralsorcery:blockmarble@2"
            ]
        },
        {
            "x": 0,
            "y": -1,
            "z": 0,
            "elements": [
                "astralsorcery:blockmarble@6"
            ]
        },
        {
            "x": -1,
            "y": 1,
            "z": 0,
            "nbt": {"casingColor":"16777215","ForgeCaps":{"nuclearcraft:capability_default_radiation_resistance":{"radiationResistance":"0.0d"}},"id":"minecraft:tilecolorablemachinecomponent"},
            "elements": [
                "modularmachinery:blockcasing@0"
            ]
        },
        {
            "x": 0,
            "y": 1,
            "z": 0,
            "nbt": {"casingColor":"16777215","ForgeCaps":{"nuclearcraft:capability_default_radiation_resistance":{"radiationResistance":"0.0d"}},"id":"minecraft:tilecolorablemachinecomponent"},
            "elements": [
                "modularmachinery:blockcasing@0"
            ]
        },
        {
            "x": -1,
            "y": -1,
            "z": 0,
            "elements": [
                "astralsorcery:blockmarble@6"
            ]
        },
        {
            "x": -2,
            "y": 1,
            "z": 2,
            "elements": [
                "astralsorcery:blockmarble@2"
            ]
        },
        {
            "x": -2,
            "y": -1,
            "z": 0,
            "elements": [
                "astralsorcery:blockmarble@6"
            ]
        },
        {
            "x": -2,
            "y": -1,
            "z": 1,
            "elements": [
                "astralsorcery:blockmarble@6"
            ]
        },
        {
            "x": -1,
            "y": 1,
            "z": 2,
            "nbt": {"casingColor":"16777215","ForgeCaps":{"nuclearcraft:capability_default_radiation_resistance":{"radiationResistance":"0.0d"}},"id":"minecraft:tilecolorablemachinecomponent"},
            "elements": [
                "modularmachinery:blockcasing@0"
            ]
        },
        {
            "x": 1,
            "y": 1,
            "z": 0,
            "nbt": {"casingColor":"16777215","ForgeCaps":{"nuclearcraft:capability_default_radiation_resistance":{"radiationResistance":"0.0d"}},"id":"minecraft:tilecolorablemachinecomponent"},
            "elements": [
                "modularmachinery:blockcasing@0"
            ]
        },
        {
            "x": 0,
            "y": 1,
            "z": 2,
            "nbt": {"casingColor":"16777215","ForgeCaps":{"nuclearcraft:capability_default_radiation_resistance":{"radiationResistance":"0.0d"}},"id":"minecraft:tilecolorablemachinecomponent"},
            "elements": [
                "modularmachinery:blockcasing@0"
            ]
        },
        {
            "x": 2,
            "y": 1,
            "z": 0,
            "elements": [
                "astralsorcery:blockmarble@2"
            ]
        },
        {
            "x": -1,
            "y": -1,
            "z": 1,
            "elements": [
                "astralsorcery:blockmarble@6"
            ]
        },
        {
            "x": 0,
            "y": -1,
            "z": 1,
            "elements": [
                "astralsorcery:blockmarble@6"
            ]
        },
        {
            "x": 1,
            "y": 1,
            "z": 2,
            "nbt": {"casingColor":"16777215","ForgeCaps":{"nuclearcraft:capability_default_radiation_resistance":{"radiationResistance":"0.0d"}},"id":"minecraft:tilecolorablemachinecomponent"},
            "elements": [
                "modularmachinery:blockcasing@0"
            ]
        },
        {
            "x": 2,
            "y": 1,
            "z": 2,
            "elements": [
                "astralsorcery:blockmarble@2"
            ]
        },
        {
            "x": 1,
            "y": -1,
            "z": 1,
            "elements": [
                "astralsorcery:blockmarble@6"
            ]
        },
        {
            "x": 2,
            "y": -1,
            "z": 1,
            "elements": [
                "astralsorcery:blockmarble@6"
            ]
        },
        {
            "x": -2,
            "y": 2,
            "z": 0,
            "elements": [
                "astralsorcery:blockmarbleslab@0"
            ]
        },
        {
            "x": -1,
            "y": 2,
            "z": 0,
            "elements": [
                "astralsorcery:blockmarbleslab@0"
            ]
        },
        {
            "x": 0,
            "y": 2,
            "z": 0,
            "elements": [
                "astralsorcery:blockmarbleslab@0"
            ]
        },
        {
            "x": -2,
            "y": 2,
            "z": 2,
            "elements": [
                "astralsorcery:blockmarbleslab@0"
            ]
        },
        {
            "x": -2,
            "y": 0,
            "z": 1,
            "elements": [
                "extendedcrafting:storage@2"
            ]
        },
        {
            "x": -1,
            "y": 2,
            "z": 2,
            "elements": [
                "astralsorcery:blockmarbleslab@0"
            ]
        },
        {
            "x": 1,
            "y": 2,
            "z": 0,
            "elements": [
                "astralsorcery:blockmarbleslab@0"
            ]
        },
        {
            "x": 0,
            "y": 2,
            "z": 2,
            "elements": [
                "astralsorcery:blockmarbleslab@0"
            ]
        },
        {
            "x": 2,
            "y": 2,
            "z": 0,
            "elements": [
                "astralsorcery:blockmarbleslab@0"
            ]
        },
        {
            "x": -1,
            "y": 0,
            "z": 1,
            "elements": [
                "astralsorcery:fluidblockliquidstarlight@0"
            ]
        },
        {
            "x": 0,
            "y": 0,
            "z": 1,
            "elements": [
                "minecraft:diamond_block@0"
            ]
        },
        {
            "x": 1,
            "y": 2,
            "z": 2,
            "elements": [
                "astralsorcery:blockmarbleslab@0"
            ]
        },
        {
            "x": 2,
            "y": 2,
            "z": 2,
            "elements": [
                "astralsorcery:blockmarbleslab@0"
            ]
        },
        {
            "x": 1,
            "y": 0,
            "z": 1,
            "elements": [
                "astralsorcery:fluidblockliquidstarlight@0"
            ]
        },
        {
            "x": 2,
            "y": 0,
            "z": 1,
            "elements": [
                "extendedcrafting:storage@2"
            ]
        },
        {
            "x": -2,
            "y": 1,
            "z": 1,
            "elements": [
                "extendedcrafting:storage@2"
            ]
        },
        {
            "x": -1,
            "y": 1,
            "z": 1,
            "elements": [
                "appliedenergistics2:smooth_sky_stone_block@0"
            ]
        },
        {
            "x": 0,
            "y": 1,
            "z": 1,
            "nbt": {"ForgeCaps":{"nuclearcraft:capability_default_radiation_resistance":{"radiationResistance":"0.0d"}},"id":"modularmagic:tileconstellationprovider"},
            "elements": [
                "modularmagic:blockconstellationprovider@0"
            ]
        },
        {
            "x": -2,
            "y": -1,
            "z": 2,
            "elements": [
                "astralsorcery:blockmarble@6"
            ]
        },
        {
            "x": 1,
            "y": 1,
            "z": 1,
            "elements": [
                "appliedenergistics2:smooth_sky_stone_block@0"
            ]
        },
        {
            "x": 2,
            "y": 1,
            "z": 1,
            "elements": [
                "extendedcrafting:storage@2"
            ]
        },
        {
            "x": -1,
            "y": -1,
            "z": 2,
            "elements": [
                "astralsorcery:blockmarble@6"
            ]
        },
        {
            "x": 0,
            "y": -1,
            "z": 2,
            "elements": [
                "astralsorcery:blockmarble@6"
            ]
        },
        {
            "x": 1,
            "y": -1,
            "z": 2,
            "elements": [
                "astralsorcery:blockmarble@6"
            ]
        },
        {
            "x": 2,
            "y": -1,
            "z": 2,
            "elements": [
                "astralsorcery:blockmarble@6"
            ]
        },
        {
            "x": -2,
            "y": 2,
            "z": 1,
            "elements": [
                "astralsorcery:blockmarbleslab@0"
            ]
        }
    ]}