{
    "parts": [
        {
            "x": -1,
            "y": 0,
            "z": 0,
            "elements": [
                "immersiveengineering:treated_wood@0"
            ]
        },
        {
            "x": -1,
            "y": 0,
            "z": 1,
            "elements": [
                "immersiveengineering:treated_wood@0"
            ]
        },
        {
            "x": -2,
            "y": 0,
            "z": 2,
            "elements": [
                "immersiveengineering:metal_decoration0@4"
            ]
        },
        {
            "x": 1,
            "y": 2,
            "z": 1,
            "nbt": {"sideConfig":,"ForgeCaps":{"nuclearcraft:capability_default_radiation_resistance":{"radiationResistance":"0.0d"}},"id":"immersiveengineering:fluidpipe","connections":"12b"},
            "elements": [
                "immersiveengineering:metal_device1@6"
            ]
        },
        {
            "x": 0,
            "y": 0,
            "z": 1,
            "elements": [
                "immersiveengineering:treated_wood@0"
            ]
        },
        {
            "x": -2,
            "y": 0,
            "z": 0,
            "elements": [
                "immersiveengineering:metal_decoration0@4"
            ]
        },
        {
            "x": 1,
            "y": 0,
            "z": 0,
            "elements": [
                "immersiveengineering:treated_wood@0"
            ]
        },
        {
            "x": -1,
            "y": 0,
            "z": 2,
            "elements": [
                "immersiveengineering:treated_wood@0"
            ]
        },
        {
            "x": 2,
            "y": 2,
            "z": 1,
            "nbt": {"owner":"AndreasThrane","idL":"-6106378302476884828L","idM":"4863570407252250259L","ForgeCaps":{"nuclearcraft:capability_default_radiation_resistance":{"radiationResistance":"0.0d"}},"infused":"0","id":"efab:tank","capacity":"16000"},
            "elements": [
                "efab:tank@0"
            ]
        },
        {
            "x": 1,
            "y": 0,
            "z": 1,
            "elements": [
                "immersiveengineering:treated_wood@0"
            ]
        },
        {
            "x": 0,
            "y": 0,
            "z": 2,
            "elements": [
                "immersiveengineering:treated_wood@0"
            ]
        },
        {
            "x": 2,
            "y": 0,
            "z": 0,
            "elements": [
                "immersiveengineering:metal_decoration0@4"
            ]
        },
        {
            "x": 2,
            "y": 0,
            "z": 1,
            "elements": [
                "immersiveengineering:treated_wood@0"
            ]
        },
        {
            "x": 1,
            "y": 0,
            "z": 2,
            "elements": [
                "immersiveengineering:treated_wood@0"
            ]
        },
        {
            "x": 2,
            "y": 0,
            "z": 2,
            "elements": [
                "immersiveengineering:metal_decoration0@4"
            ]
        },
        {
            "x": -2,
            "y": 7,
            "z": 1,
            "nbt": {"sideConfig":,"ForgeCaps":{"nuclearcraft:capability_default_radiation_resistance":{"radiationResistance":"0.0d"}},"id":"immersiveengineering:fluidpipe","connections":"9b"},
            "elements": [
                "immersiveengineering:metal_device1@6"
            ]
        },
        {
            "x": -1,
            "y": 7,
            "z": 1,
            "nbt": {"sideConfig":,"ForgeCaps":{"nuclearcraft:capability_default_radiation_resistance":{"radiationResistance":"0.0d"}},"id":"immersiveengineering:fluidpipe","connections":"12b"},
            "elements": [
                "immersiveengineering:metal_device1@6"
            ]
        },
        {
            "x": 0,
            "y": 7,
            "z": 1,
            "nbt": {"sideConfig":,"ForgeCaps":{"nuclearcraft:capability_default_radiation_resistance":{"radiationResistance":"0.0d"}},"id":"immersiveengineering:fluidpipe","connections":"5b"},
            "elements": [
                "immersiveengineering:metal_device1@6"
            ]
        },
        {
            "x": -2,
            "y": 5,
            "z": 1,
            "nbt": {"sideConfig":,"ForgeCaps":{"nuclearcraft:capability_default_radiation_resistance":{"radiationResistance":"0.0d"}},"id":"immersiveengineering:fluidpipe","connections":"3b"},
            "elements": [
                "immersiveengineering:metal_device1@6"
            ]
        },
        {
            "x": -2,
            "y": 3,
            "z": 1,
            "nbt": {"owner":"AndreasThrane","idL":"-6106378302476884828L","idM":"4863570407252250259L","ForgeCaps":{"nuclearcraft:capability_default_radiation_resistance":{"radiationResistance":"0.0d"}},"infused":"0","id":"efab:tank","capacity":"0"},
            "elements": [
                "efab:tank@0"
            ]
        },
        {
            "x": -2,
            "y": 1,
            "z": 0,
            "nbt": {"casingColor":"16777215","ForgeCaps":{"nuclearcraft:capability_default_radiation_resistance":{"radiationResistance":"0.0d"}},"id":"minecraft:tilecolorablemachinecomponent"},
            "elements": [
                "modularmachinery:blockcasing@0"
            ]
        },
        {
            "x": -1,
            "y": 1,
            "z": 0,
            "elements": [
                "adchimneys:red_nether_brick@1"
            ]
        },
        {
            "x": -2,
            "y": 1,
            "z": 1,
            "nbt": {"casingColor":"16777215","ForgeCaps":{"nuclearcraft:capability_default_radiation_resistance":{"radiationResistance":"0.0d"}},"id":"minecraft:tilecolorablemachinecomponent"},
            "elements": [
                "modularmachinery:blockcasing@0"
            ]
        },
        {
            "x": 0,
            "y": 1,
            "z": 0,
            "elements": [
                "adchimneys:red_nether_brick@1"
            ]
        },
        {
            "x": -1,
            "y": 1,
            "z": 1,
            "elements": [
                "adchimneys:red_nether_brick@1"
            ]
        },
        {
            "x": -2,
            "y": 1,
            "z": 2,
            "nbt": {"casingColor":"16777215","ForgeCaps":{"nuclearcraft:capability_default_radiation_resistance":{"radiationResistance":"0.0d"}},"id":"minecraft:tilecolorablemachinecomponent"},
            "elements": [
                "modularmachinery:blockcasing@0"
            ]
        },
        {
            "x": 0,
            "y": 1,
            "z": 1,
            "nbt": {"ForgeCaps":{"nuclearcraft:capability_default_radiation_resistance":{"radiationResistance":"0.0d"}},"facing":"4","active":"0b","ifluxEnergy":"0","id":"immersiveengineering:furnaceheater"},
            "elements": [
                "immersiveengineering:metal_device1@1"
            ]
        },
        {
            "x": 2,
            "y": 3,
            "z": 1,
            "nbt": {"owner":"AndreasThrane","idL":"-6106378302476884828L","idM":"4863570407252250259L","ForgeCaps":{"nuclearcraft:capability_default_radiation_resistance":{"radiationResistance":"0.0d"}},"infused":"0","id":"efab:tank","capacity":"0"},
            "elements": [
                "efab:tank@0"
            ]
        },
        {
            "x": 1,
            "y": 1,
            "z": 0,
            "elements": [
                "adchimneys:red_nether_brick@1"
            ]
        },
        {
            "x": -1,
            "y": 1,
            "z": 2,
            "elements": [
                "adchimneys:red_nether_brick@1"
            ]
        },
        {
            "x": 0,
            "y": 1,
            "z": 2,
            "elements": [
                "adchimneys:red_nether_brick@1"
            ]
        },
        {
            "x": 1,
            "y": 1,
            "z": 1,
            "elements": [
                "adchimneys:red_nether_brick@1"
            ]
        },
        {
            "x": 2,
            "y": 1,
            "z": 0,
            "nbt": {"casingColor":"16777215","ForgeCaps":{"nuclearcraft:capability_default_radiation_resistance":{"radiationResistance":"0.0d"}},"id":"minecraft:tilecolorablemachinecomponent"},
            "elements": [
                "modularmachinery:blockcasing@0"
            ]
        },
        {
            "x": 1,
            "y": 1,
            "z": 2,
            "elements": [
                "adchimneys:red_nether_brick@1"
            ]
        },
        {
            "x": 2,
            "y": 1,
            "z": 1,
            "nbt": {"casingColor":"16777215","ForgeCaps":{"nuclearcraft:capability_default_radiation_resistance":{"radiationResistance":"0.0d"}},"id":"minecraft:tilecolorablemachinecomponent"},
            "elements": [
                "modularmachinery:blockcasing@0"
            ]
        },
        {
            "x": 2,
            "y": 1,
            "z": 2,
            "nbt": {"casingColor":"16777215","ForgeCaps":{"nuclearcraft:capability_default_radiation_resistance":{"radiationResistance":"0.0d"}},"id":"minecraft:tilecolorablemachinecomponent"},
            "elements": [
                "modularmachinery:blockcasing@0"
            ]
        },
        {
            "x": -2,
            "y": 6,
            "z": 1,
            "nbt": {"sideConfig":,"ForgeCaps":{"nuclearcraft:capability_default_radiation_resistance":{"radiationResistance":"0.0d"}},"id":"immersiveengineering:fluidpipe","connections":"3b"},
            "elements": [
                "immersiveengineering:metal_device1@6"
            ]
        },
        {
            "x": -2,
            "y": 4,
            "z": 1,
            "nbt": {"owner":"AndreasThrane","idL":"-6106378302476884828L","idM":"4863570407252250259L","ForgeCaps":{"nuclearcraft:capability_default_radiation_resistance":{"radiationResistance":"0.0d"}},"infused":"0","id":"efab:tank","capacity":"0"},
            "elements": [
                "efab:tank@0"
            ]
        },
        {
            "x": -2,
            "y": 2,
            "z": 1,
            "nbt": {"owner":"AndreasThrane","idL":"-6106378302476884828L","idM":"4863570407252250259L","ForgeCaps":{"nuclearcraft:capability_default_radiation_resistance":{"radiationResistance":"0.0d"}},"infused":"0","id":"efab:tank","capacity":"24000"},
            "elements": [
                "efab:tank@0"
            ]
        },
        {
            "x": -2,
            "y": 0,
            "z": 1,
            "elements": [
                "immersiveengineering:treated_wood@0"
            ]
        },
        {
            "x": 0,
            "y": 2,
            "z": 1,
            "nbt": {"offset":,"pos":"4","ForgeCaps":{"nuclearcraft:capability_default_radiation_resistance":{"radiationResistance":"0.0d"}},"facing":"5","id":"immersiveengineering:sheetmetaltank","formed":"1b","tank":{"Empty":""},"mirrored":"0b"},
            "elements": [
                "immersiveengineering:metal_multiblock@2"
            ]
        }
    ]}